{"uuid": "400cc186-416b-4a0e-b4ca-c8d3cacc3c29", "children": ["0adf2a82-8129-4c7c-b5f1-929faeeac4ed"], "befores": [{"name": "driver", "status": "broken", "statusDetails": {"message": "selenium.common.exceptions.WebDriverException: Message: [BROWSERSTACK_INVALID_APP_CAP] The app_url/ custom_id/ shareable_id specified in the 'app' capability in your test script is invalid. Please update the 'app' capability with a valid value and try again.\n\n", "trace": "  File \"/Library/Frameworks/Python.framework/Versions/3.10/lib/python3.10/site-packages/pluggy/_callers.py\", line 39, in _multicall\n    res = hook_impl.function(*args)\n  File \"/Library/Frameworks/Python.framework/Versions/3.10/lib/python3.10/site-packages/_pytest/fixtures.py\", line 1128, in pytest_fixture_setup\n    result = call_fixture_func(fixturefunc, request, kwargs)\n  File \"/Library/Frameworks/Python.framework/Versions/3.10/lib/python3.10/site-packages/_pytest/fixtures.py\", line 900, in call_fixture_func\n    fixture_result = next(generator)\n  File \"/Users/yaroslav.petryk/Desktop/projects/browserstack_appium/tests/conftest.py\", line 8, in driver\n    driver = webdriver.Remote(url, capabilities)\n  File \"/Library/Frameworks/Python.framework/Versions/3.10/lib/python3.10/site-packages/appium/webdriver/webdriver.py\", line 257, in __init__\n    super().__init__(\n  File \"/Library/Frameworks/Python.framework/Versions/3.10/lib/python3.10/site-packages/browserstack_sdk/__init__.py\", line 1670, in bstack11llll11l_opy_\n    bstack1l1lll111_opy_(self, command_executor=command_executor,\n  File \"/Library/Frameworks/Python.framework/Versions/3.10/lib/python3.10/site-packages/selenium/webdriver/remote/webdriver.py\", line 272, in __init__\n    self.start_session(capabilities, browser_profile)\n  File \"/Library/Frameworks/Python.framework/Versions/3.10/lib/python3.10/site-packages/appium/webdriver/webdriver.py\", line 346, in start_session\n    response = self.execute(RemoteCommand.NEW_SESSION, w3c_caps)\n  File \"/Library/Frameworks/Python.framework/Versions/3.10/lib/python3.10/site-packages/selenium/webdriver/remote/webdriver.py\", line 429, in execute\n    self.error_handler.check_response(response)\n  File \"/Library/Frameworks/Python.framework/Versions/3.10/lib/python3.10/site-packages/selenium/webdriver/remote/errorhandler.py\", line 243, in check_response\n    raise exception_class(message, screen, stacktrace)\n"}, "start": 1693144771053, "stop": 1693144771722}], "start": 1693144771053, "stop": 1693144772201}